Workbook

Sheet Cover
A1: Capital Structure & Valuation — Indian FMCG (FY2022–FY2026)
A2: 8 firms · Screener.in standalone statements · built by the analysis/scripts pipeline — regenerate with export_to_excel.py
B4: The question | C4: Does capital structure explain profitability and valuation differences across Indian FMCG firms — and where does the optimal leverage band lie?
B6: Sheets
B7: Raw Data | C7: single source of truth — statement inputs (blue) + derived formula columns
B8: Market Data | C8: July-2026 market snapshot per firm (inputs to WACC / DCF / Comps)
B9: Ratio Analysis | C9: 10 ratios per firm-year, live formulas + heatmaps + ROE trend chart
B10: DuPont Analysis | C10: 5-step ROE decomposition, identity check, ln-contribution chart
B11: Capital Structure | C11: leverage bands via IF formulas + D/E and coverage charts
B12: Leverage Threshold | C12: where ROE peaks across the D/E spectrum (python bins + live scatter)
B13: WACC | C13: CAPM assumptions (yellow) → per-firm WACC + book-weight evolution
B14: Correlation Matrix | C14: ratio correlation heatmap + multicollinearity shortlist
B15: Regression Analysis | C15: OLS: ROE ~ D/E + NetMargin + log(assets), interpretation + fit plot
B16: DCF - FCFF | C16: 5-year FCFF DCF per firm → EV → equity → value per share vs market
B17: DCF - FCFE | C17: equity-direct DCF at cost of equity; gap vs FCFF = leverage effect
B18: Comps | C18: EV/EBITDA vs sector median — premium / discount flags
B19: Sensitivity Analysis | C19: value-per-share grids: WACC ±200bp × terminal g 1–5% per firm
B21: Colour legend
B22: blue font | C22: hardcoded input — traceable to data/cleaned/ CSVs
B23: black font | C23: live Excel formula — recalculates when Raw Data changes
B24: yellow fill | C24: assumption meant to be challenged (Rf, ERP, beta, growth…)
B25: grey fill | C25: computed in python (script credited beside the block)
B27: Sources
B28: HUL | C28: https://www.screener.in/company/HINDUNILVR/
B29: ITC | C29: https://www.screener.in/company/ITC/
B30: Dabur | C30: https://www.screener.in/company/DABUR/
B31: Marico | C31: https://www.screener.in/company/MARICO/
B32: Colgate | C32: https://www.screener.in/company/COLPAL/
B33: Nestle | C33: https://www.screener.in/company/NESTLEIND/
B34: Godrej | C34: https://www.screener.in/company/GODREJCP/
B35: Emami | C35: https://www.screener.in/company/EMAMILTD/
B37: Statements: standalone, FY2015–FY2026 scraped 2026-07 · schedules (cash, payables, capex detail) via the Screener schedules API · market snapshot as of July 2026

Sheet Raw Data
A1: Company | B1: Year | C1: Revenue | D1: OperatingProfit | E1: OtherIncome | F1: InterestExpense | G1: Depreciation | H1: PBT | I1: TaxPct | J1: NetProfit | K1: ShareCapital | L1: Reserves | M1: TotalDebt | N1: TotalAssets | O1: Cash | P1: Inventories | Q1: TradeReceivables | R1: OtherLiabilities | S1: OperatingCashFlow | T1: FreeCashFlow | U1: PrevTotalDebt | V1: TaxRate | W1: EBIT | X1: EBITDA | Y1: TotalEquity | Z1: CurrentAssets | AA1: CurrentLiabilities | AB1: Capex | AC1: NetBorrowing | AD1: SharesOutstanding
A2: HUL | B2: FY2022 | C2: 51193 | D2: 12503 | E2: 359 | F2: 98 | G2: 1025 | H2: 11739 | I2: 25 | J2: 8818 | K2: 235 | L2: 48525 | M2: 971 | N2: 69737 | O2: 3618 | P2: 3890 | Q2: 1932 | R2: 20006 | S2: 8964 | T2: 8220 | U2: 943 | V2: =I2/100 | W2: =H2+F2 | X2: =W2+G2 | Y2: =K2+L2 | Z2: =O2+P2+Q2 | AA2: =R2 | AB2: =S2-T2 | AC2: =M2-U2 | AD2: =K2/INDEX('Market Data'!$D$2:$D$9,MATCH(A2,'Market Data'!$A$2:$A$9,0))
A3: HUL | B3: FY2023 | C3: 59144 | D3: 13632 | E3: 578 | F3: 101 | G3: 1030 | H3: 13079 | I3: 24 | J3: 9962 | K3: 235 | L3: 49986 | M3: 1039 | N3: 71825 | O3: 4422 | P3: 4031 | Q3: 2735 | R3: 20565 | S3: 9626 | T3: 8765 | U3: 971 | V3: =I3/100 | W3: =H3+F3 | X3: =W3+G3 | Y3: =K3+L3 | Z3: =O3+P3+Q3 | AA3: =R3 | AB3: =S3-T3 | AC3: =M3-U3 | AD3: =K3/INDEX('Market Data'!$D$2:$D$9,MATCH(A3,'Market Data'!$A$2:$A$9,0))
A4: HUL | B4: FY2024 | C4: 60469 | D4: 14190 | E4: 884 | F4: 302 | G4: 1097 | H4: 13675 | I4: 26 | J4: 10114 | K4: 235 | L4: 50738 | M4: 1374 | N4: 77076 | O4: 7216 | P4: 3812 | Q4: 2690 | R4: 24729 | S4: 14884 | T4: 13586 | U4: 1039 | V4: =I4/100 | W4: =H4+F4 | X4: =W4+G4 | Y4: =K4+L4 | Z4: =O4+P4+Q4 | AA4: =R4 | AB4: =S4-T4 | AC4: =M4-U4 | AD4: =K4/INDEX('Market Data'!$D$2:$D$9,MATCH(A4,'Market Data'!$A$2:$A$9,0))
A5: HUL | B5: FY2025 | C5: 59676 | D5: 14144 | E5: 1632 | F5: 350 | G5: 1122 | H5: 14304 | I5: 26 | J5: 10644 | K5: 235 | L5: 48918 | M5: 1537 | N5: 78313 | O5: 7293 | P5: 4161 | Q5: 3450 | R5: 27623 | S5: 11606 | T5: 10470 | U5: 1374 | V5: =I5/100 | W5: =H5+F5 | X5: =W5+G5 | Y5: =K5+L5 | Z5: =O5+P5+Q5 | AA5: =R5 | AB5: =S5-T5 | AC5: =M5-U5 | AD5: =K5/INDEX('Market Data'!$D$2:$D$9,MATCH(A5,'Market Data'!$A$2:$A$9,0))
A6: HUL | B6: FY2026 | C6: 61975 | D6: 14464 | E6: 5572 | F6: 363 | G6: 1186 | H6: 18487 | I6: 17 | J6: 15427 | K6: 235 | L6: 48988 | M6: 1325 | N6: 77982 | O6: 2830 | P6: 4383 | Q6: 3037 | R6: 27434 | S6: 10496 | T6: 9251 | U6: 1537 | V6: =I6/100 | W6: =H6+F6 | X6: =W6+G6 | Y6: =K6+L6 | Z6: =O6+P6+Q6 | AA6: =R6 | AB6: =S6-T6 | AC6: =M6-U6 | AD6: =K6/INDEX('Market Data'!$D$2:$D$9,MATCH(A6,'Market Data'!$A$2:$A$9,0))
A7: ITC | B7: FY2022 | C7: 56341 | D7: 18893 | E7: 2649 | F7: 61 | G7: 1652 | H7: 19830 | I7: 24 | J7: 15058 | K7: 1232 | L7: 60167 | M7: 311 | N7: 75092 | O7: 3878 | P7: 9998 | Q7: 1952 | R7: 13382 | S7: 14808 | T7: 13133 | U7: 329 | V7: =I7/100 | W7: =H7+F7 | X7: =W7+G7 | Y7: =K7+L7 | Z7: =O7+P7+Q7 | AA7: =R7 | AB7: =S7-T7 | AC7: =M7-U7 | AD7: =K7/INDEX('Market Data'!$D$2:$D$9,MATCH(A7,'Market Data'!$A$2:$A$9,0))
A8: ITC | B8: FY2023 | C8: 66043 | D8: 23981 | E8: 2506 | F8: 74 | G8: 1663 | H8: 24750 | I8: 24 | J8: 18753 | K8: 1243 | L8: 66351 | M8: 325 | N8: 82262 | O8: 3831 | P8: 10594 | Q8: 2321 | R8: 14343 | S8: 17912 | T8: 16102 | U8: 311 | V8: =I8/100 | W8: =H8+F8 | X8: =W8+G8 | Y8: =K8+L8 | Z8: =O8+P8+Q8 | AA8: =R8 | AB8: =S8-T8 | AC8: =M8-U8 | AD8: =K8/INDEX('Market Data'!$D$2:$D$9,MATCH(A8,'Market Data'!$A$2:$A$9,0))
A9: ITC | B9: FY2024 | C9: 62628 | D9: 23435 | E9: 4100 | F9: 34 | G9: 1357 | H9: 26144 | I9: 22 | J9: 20422 | K9: 1248 | L9: 70985 | M9: 312 | N9: 87328 | O9: 6218 | P9: 12632 | Q9: 3311 | R9: 14782 | S9: 16118 | T9: 13572 | U9: 325 | V9: =I9/100 | W9: =H9+F9 | X9: =W9+G9 | Y9: =K9+L9 | Z9: =O9+P9+Q9 | AA9: =R9 | AB9: =S9-T9 | AC9: =M9-U9 | AD9: =K9/INDEX('Market Data'!$D$2:$D$9,MATCH(A9,'Market Data'!$A$2:$A$9,0))
A10: ITC | B10: FY2025 | C10: 69326 | D10: 23906 | E10: 19206 | F10: 36 | G10: 1442 | H10: 41634 | I10: 15 | J10: 35197 | K10: 1251 | L10: 66642 | M10: 157 | N10: 84005 | O10: 3185 | P10: 15061 | Q10: 3911 | R10: 15954 | S10: 16754 | T10: 15123 | U10: 312 | V10: =I10/100 | W10: =H10+F10 | X10: =W10+G10 | Y10: =K10+L10 | Z10: =O10+P10+Q10 | AA10: =R10 | AB10: =S10-T10 | AC10: =M10-U10 | AD10: =K10/INDEX('Market Data'!$D$2:$D$9,MATCH(A10,'Market Data'!$A$2:$A$9,0))
A11: ITC | B11: FY2026 | C11: 71984 | D11: 25196 | E11: 3115 | F11: 70 | G11: 1474 | H11: 26768 | I11: 24 | J11: 20286 | K11: 1253 | L11: 68676 | M11: 2162 | N11: 88916 | O11: 2136 | P11: 17932 | Q11: 2926 | R11: 16825 | S11: 17095 | T11: 15075 | U11: 157 | V11: =I11/100 | W11: =H11+F11 | X11: =W11+G11 | Y11: =K11+L11 | Z11: =O11+P11+Q11 | AA11: =R11 | AB11: =S11-T11 | AC11: =M11-U11 | AD11: =K11/INDEX('Market Data'!$D$2:$D$9,MATCH(A11,'Market Data'!$A$2:$A$9,0))
A12: Dabur | B12: FY2022 | C12: 8180 | D12: 1734 | E12: 341 | F12: 19 | G12: 160 | H12: 1896 | I12: 24 | J12: 1433 | K12: 177 | L12: 5687 | M12: 560 | N12: 8592 | O12: 136 | P12: 1238 | Q12: 455 | R12: 2168 | S12: 1320 | T12: 1025 | U12: 180 | V12: =I12/100 | W12: =H12+F12 | X12: =W12+G12 | Y12: =K12+L12 | Z12: =O12+P12+Q12 | AA12: =R12 | AB12: =S12-T12 | AC12: =M12-U12 | AD12: =K12/INDEX('Market Data'!$D$2:$D$9,MATCH(A12,'Market Data'!$A$2:$A$9,0))
A13: Dabur | B13: FY2023 | C13: 8684 | D13: 1701 | E13: 363 | F13: 46 | G13: 188 | H13: 1829 | I13: 25 | J13: 1373 | K13: 177 | L13: 6110 | M13: 615 | N13: 9352 | O13: 33 | P13: 1224 | Q13: 561 | R13: 2450 | S13: 1562 | T13: 1173 | U13: 560 | V13: =I13/100 | W13: =H13+F13 | X13: =W13+G13 | Y13: =K13+L13 | Z13: =O13+P13+Q13 | AA13: =R13 | AB13: =S13-T13 | AC13: =M13-U13 | AD13: =K13/INDEX('Market Data'!$D$2:$D$9,MATCH(A13,'Market Data'!$A$2:$A$9,0))
... A41: Emami | B41: FY2026 | C41: 3048 | D41: 950 | E41: 108 | F41: 2 | G41: 156 | H41: 901 | I41: 7 | J41: 842 | K41: 44 | L41: 3112 | M41: 92 | N41: 3726 | O41: 317 | P41: 334 | Q41: 190 | R41: 478 | S41: 794 | T41: 760 | U41: 14 | V41: =I41/100 | W41: =H41+F41 | X41: =W41+G41 | Y41: =K41+L41 | Z41: =O41+P41+Q41 | AA41: =R41 | AB41: =S41-T41 | AC41: =M41-U41 | AD41: =K41/INDEX('Market Data'!$D$2:$D$9,MATCH(A41,'Market Data'!$A$2:$A$9,0))
A43: All figures ₹ Cr (SharesOutstanding in Cr shares; TaxPct in %). Blue = input from data/cleaned/. Black = derived formula. PrevTotalDebt = prior-FY borrowings (for ΔDebt).

Sheet Market Data
A1: Company | B1: MarketCap | C1: CurrentPrice | D1: FaceValue | E1: StockPE | F1: BookValue | G1: DividendYieldPct | H1: ScreenerROCEPct | I1: ScreenerROEPct
A2: HUL | B2: 512511 | C2: 2182 | D2: 1 | E2: 33.6 | F2: 210 | G2: 1.88 | H2: 28.1 | I2: 31
A3: ITC | B3: 363667 | C3: 290 | D3: 1 | E3: 17.8 | F3: 55.8 | G3: 4.99 | H3: 38.6 | I3: 29.6
A4: Dabur | B4: 78915 | C4: 445 | D4: 1 | E4: 52.5 | F4: 42.4 | G4: 1.85 | H4: 25.1 | I4: 20.1
A5: Marico | B5: 110506 | C5: 851 | D5: 1 | E5: 56.9 | F5: 44.7 | G5: 0.47 | H5: 41.5 | I5: 36.7
A6: Colgate | B6: 56334 | C6: 2072 | D6: 1 | E6: 41.9 | F6: 58.2 | G6: 2.46 | H6: 108 | I6: 82.7
A7: Nestle | B7: 279940 | C7: 1454 | D7: 1 | E7: 81.2 | F7: 27.5 | G7: 0.83 | H7: 84.1 | I7: 73.2
A8: Godrej | B8: 106775 | C8: 1044 | D8: 1 | E8: 68.6 | F8: 76.7 | G8: 1.92 | H8: 20.9 | I8: 19.2
A9: Emami | B9: 18120 | C9: 415 | D9: 1 | E9: 21.3 | F9: 72.3 | G9: 2.41 | H9: 29.8 | I9: 28.3
A11: Screener.in snapshot, July 2026 (data/cleaned/market_snapshot.csv). MarketCap ₹ Cr; prices/face/book ₹ per share; yields & returns in %.

Sheet Ratio Analysis
A1: Company | B1: Year | C1: ROE | D1: ROA | E1: NetMargin | F1: EBITMargin | G1: AssetTurnover | H1: EquityMultiplier | I1: DebtToEquity | J1: DebtRatio | K1: InterestCoverage | L1: CurrentRatio | N1: ROE trend
A2: ='Raw Data'!A2 | B2: ='Raw Data'!B2 | C2: ='Raw Data'!J2/'Raw Data'!Y2 | D2: ='Raw Data'!J2/'Raw Data'!N2 | E2: ='Raw Data'!J2/'Raw Data'!C2 | F2: ='Raw Data'!W2/'Raw Data'!C2 | G2: ='Raw Data'!C2/'Raw Data'!N2 | H2: ='Raw Data'!N2/'Raw Data'!Y2 | I2: ='Raw Data'!M2/'Raw Data'!Y2 | J2: ='Raw Data'!M2/'Raw Data'!N2 | K2: =IF('Raw Data'!F2=0,NA(),'Raw Data'!W2/'Raw Data'!F2) | L2: ='Raw Data'!Z2/'Raw Data'!AA2 | O2: ='Raw Data'!A2 | P2: ='Raw Data'!A7 | Q2: ='Raw Data'!A12 | R2: ='Raw Data'!A17 | S2: ='Raw Data'!A22 | T2: ='Raw Data'!A27 | U2: ='Raw Data'!A32 | V2: ='Raw Data'!A37
A3: ='Raw Data'!A3 | B3: ='Raw Data'!B3 | C3: ='Raw Data'!J3/'Raw Data'!Y3 | D3: ='Raw Data'!J3/'Raw Data'!N3 | E3: ='Raw Data'!J3/'Raw Data'!C3 | F3: ='Raw Data'!W3/'Raw Data'!C3 | G3: ='Raw Data'!C3/'Raw Data'!N3 | H3: ='Raw Data'!N3/'Raw Data'!Y3 | I3: ='Raw Data'!M3/'Raw Data'!Y3 | J3: ='Raw Data'!M3/'Raw Data'!N3 | K3: =IF('Raw Data'!F3=0,NA(),'Raw Data'!W3/'Raw Data'!F3) | L3: ='Raw Data'!Z3/'Raw Data'!AA3 | N3: FY2022 | O3: =C2 | P3: =C7 | Q3: =C12 | R3: =C17 | S3: =C22 | T3: =C27 | U3: =C32 | V3: =C37
A4: ='Raw Data'!A4 | B4: ='Raw Data'!B4 | C4: ='Raw Data'!J4/'Raw Data'!Y4 | D4: ='Raw Data'!J4/'Raw Data'!N4 | E4: ='Raw Data'!J4/'Raw Data'!C4 | F4: ='Raw Data'!W4/'Raw Data'!C4 | G4: ='Raw Data'!C4/'Raw Data'!N4 | H4: ='Raw Data'!N4/'Raw Data'!Y4 | I4: ='Raw Data'!M4/'Raw Data'!Y4 | J4: ='Raw Data'!M4/'Raw Data'!N4 | K4: =IF('Raw Data'!F4=0,NA(),'Raw Data'!W4/'Raw Data'!F4) | L4: ='Raw Data'!Z4/'Raw Data'!AA4 | N4: FY2023 | O4: =C3 | P4: =C8 | Q4: =C13 | R4: =C18 | S4: =C23 | T4: =C28 | U4: =C33 | V4: =C38
A5: ='Raw Data'!A5 | B5: ='Raw Data'!B5 | C5: ='Raw Data'!J5/'Raw Data'!Y5 | D5: ='Raw Data'!J5/'Raw Data'!N5 | E5: ='Raw Data'!J5/'Raw Data'!C5 | F5: ='Raw Data'!W5/'Raw Data'!C5 | G5: ='Raw Data'!C5/'Raw Data'!N5 | H5: ='Raw Data'!N5/'Raw Data'!Y5 | I5: ='Raw Data'!M5/'Raw Data'!Y5 | J5: ='Raw Data'!M5/'Raw Data'!N5 | K5: =IF('Raw Data'!F5=0,NA(),'Raw Data'!W5/'Raw Data'!F5) | L5: ='Raw Data'!Z5/'Raw Data'!AA5 | N5: FY2024 | O5: =C4 | P5: =C9 | Q5: =C14 | R5: =C19 | S5: =C24 | T5: =C29 | U5: =C34 | V5: =C39
A6: ='Raw Data'!A6 | B6: ='Raw Data'!B6 | C6: ='Raw Data'!J6/'Raw Data'!Y6 | D6: ='Raw Data'!J6/'Raw Data'!N6 | E6: ='Raw Data'!J6/'Raw Data'!C6 | F6: ='Raw Data'!W6/'Raw Data'!C6 | G6: ='Raw Data'!C6/'Raw Data'!N6 | H6: ='Raw Data'!N6/'Raw Data'!Y6 | I6: ='Raw Data'!M6/'Raw Data'!Y6 | J6: ='Raw Data'!M6/'Raw Data'!N6 | K6: =IF('Raw Data'!F6=0,NA(),'Raw Data'!W6/'Raw Data'!F6) | L6: ='Raw Data'!Z6/'Raw Data'!AA6 | N6: FY2025 | O6: =C5 | P6: =C10 | Q6: =C15 | R6: =C20 | S6: =C25 | T6: =C30 | U6: =C35 | V6: =C40
A7: ='Raw Data'!A7 | B7: ='Raw Data'!B7 | C7: ='Raw Data'!J7/'Raw Data'!Y7 | D7: ='Raw Data'!J7/'Raw Data'!N7 | E7: ='Raw Data'!J7/'Raw Data'!C7 | F7: ='Raw Data'!W7/'Raw Data'!C7 | G7: ='Raw Data'!C7/'Raw Data'!N7 | H7: ='Raw Data'!N7/'Raw Data'!Y7 | I7: ='Raw Data'!M7/'Raw Data'!Y7 | J7: ='Raw Data'!M7/'Raw Data'!N7 | K7: =IF('Raw Data'!F7=0,NA(),'Raw Data'!W7/'Raw Data'!F7) | L7: ='Raw Data'!Z7/'Raw Data'!AA7 | N7: FY2026 | O7: =C6 | P7: =C11 | Q7: =C16 | R7: =C21 | S7: =C26 | T7: =C31 | U7: =C36 | V7: =C41
A8: ='Raw Data'!A8 | B8: ='Raw Data'!B8 | C8: ='Raw Data'!J8/'Raw Data'!Y8 | D8: ='Raw Data'!J8/'Raw Data'!N8 | E8: ='Raw Data'!J8/'Raw Data'!C8 | F8: ='Raw Data'!W8/'Raw Data'!C8 | G8: ='Raw Data'!C8/'Raw Data'!N8 | H8: ='Raw Data'!N8/'Raw Data'!Y8 | I8: ='Raw Data'!M8/'Raw Data'!Y8 | J8: ='Raw Data'!M8/'Raw Data'!N8 | K8: =IF('Raw Data'!F8=0,NA(),'Raw Data'!W8/'Raw Data'!F8) | L8: ='Raw Data'!Z8/'Raw Data'!AA8
A9: ='Raw Data'!A9 | B9: ='Raw Data'!B9 | C9: ='Raw Data'!J9/'Raw Data'!Y9 | D9: ='Raw Data'!J9/'Raw Data'!N9 | E9: ='Raw Data'!J9/'Raw Data'!C9 | F9: ='Raw Data'!W9/'Raw Data'!C9 | G9: ='Raw Data'!C9/'Raw Data'!N9 | H9: ='Raw Data'!N9/'Raw Data'!Y9 | I9: ='Raw Data'!M9/'Raw Data'!Y9 | J9: ='Raw Data'!M9/'Raw Data'!N9 | K9: =IF('Raw Data'!F9=0,NA(),'Raw Data'!W9/'Raw Data'!F9) | L9: ='Raw Data'!Z9/'Raw Data'!AA9
A10: ='Raw Data'!A10 | B10: ='Raw Data'!B10 | C10: ='Raw Data'!J10/'Raw Data'!Y10 | D10: ='Raw Data'!J10/'Raw Data'!N10 | E10: ='Raw Data'!J10/'Raw Data'!C10 | F10: ='Raw Data'!W10/'Raw Data'!C10 | G10: ='Raw Data'!C10/'Raw Data'!N10 | H10: ='Raw Data'!N10/'Raw Data'!Y10 | I10: ='Raw Data'!M10/'Raw Data'!Y10 | J10: ='Raw Data'!M10/'Raw Data'!N10 | K10: =IF('Raw Data'!F10=0,NA(),'Raw Data'!W10/'Raw Data'!F10) | L10: ='Raw Data'!Z10/'Raw Data'!AA10
A11: ='Raw Data'!A11 | B11: ='Raw Data'!B11 | C11: ='Raw Data'!J11/'Raw Data'!Y11 | D11: ='Raw Data'!J11/'Raw Data'!N11 | E11: ='Raw Data'!J11/'Raw Data'!C11 | F11: ='Raw Data'!W11/'Raw Data'!C11 | G11: ='Raw Data'!C11/'Raw Data'!N11 | H11: ='Raw Data'!N11/'Raw Data'!Y11 | I11: ='Raw Data'!M11/'Raw Data'!Y11 | J11: ='Raw Data'!M11/'Raw Data'!N11 | K11: =IF('Raw Data'!F11=0,NA(),'Raw Data'!W11/'Raw Data'!F11) | L11: ='Raw Data'!Z11/'Raw Data'!AA11
A12: ='Raw Data'!A12 | B12: ='Raw Data'!B12 | C12: ='Raw Data'!J12/'Raw Data'!Y12 | D12: ='Raw Data'!J12/'Raw Data'!N12 | E12: ='Raw Data'!J12/'Raw Data'!C12 | F12: ='Raw Data'!W12/'Raw Data'!C12 | G12: ='Raw Data'!C12/'Raw Data'!N12 | H12: ='Raw Data'!N12/'Raw Data'!Y12 | I12: ='Raw Data'!M12/'Raw Data'!Y12 | J12: ='Raw Data'!M12/'Raw Data'!N12 | K12: =IF('Raw Data'!F12=0,NA(),'Raw Data'!W12/'Raw Data'!F12) | L12: ='Raw Data'!Z12/'Raw Data'!AA12
A13: ='Raw Data'!A13 | B13: ='Raw Data'!B13 | C13: ='Raw Data'!J13/'Raw Data'!Y13 | D13: ='Raw Data'!J13/'Raw Data'!N13 | E13: ='Raw Data'!J13/'Raw Data'!C13 | F13: ='Raw Data'!W13/'Raw Data'!C13 | G13: ='Raw Data'!C13/'Raw Data'!N13 | H13: ='Raw Data'!N13/'Raw Data'!Y13 | I13: ='Raw Data'!M13/'Raw Data'!Y13 | J13: ='Raw Data'!M13/'Raw Data'!N13 | K13: =IF('Raw Data'!F13=0,NA(),'Raw Data'!W13/'Raw Data'!F13) | L13: ='Raw Data'!Z13/'Raw Data'!AA13
A14: ='Raw Data'!A14 | B14: ='Raw Data'!B14 | C14: ='Raw Data'!J14/'Raw Data'!Y14 | D14: ='Raw Data'!J14/'Raw Data'!N14 | E14: ='Raw Data'!J14/'Raw Data'!C14 | F14: ='Raw Data'!W14/'Raw Data'!C14 | G14: ='Raw Data'!C14/'Raw Data'!N14 | H14: ='Raw Data'!N14/'Raw Data'!Y14 | I14: ='Raw Data'!M14/'Raw Data'!Y14 | J14: ='Raw Data'!M14/'Raw Data'!N14 | K14: =IF('Raw Data'!F14=0,NA(),'Raw Data'!W14/'Raw Data'!F14) | L14: ='Raw Data'!Z14/'Raw Data'!AA14
A15: ='Raw Data'!A15 | B15: ='Raw Data'!B15 | C15: ='Raw Data'!J15/'Raw Data'!Y15 | D15: ='Raw Data'!J15/'Raw Data'!N15 | E15: ='Raw Data'!J15/'Raw Data'!C15 | F15: ='Raw Data'!W15/'Raw Data'!C15 | G15: ='Raw Data'!C15/'Raw Data'!N15 | H15: ='Raw Data'!N15/'Raw Data'!Y15 | I15: ='Raw Data'!M15/'Raw Data'!Y15 | J15: ='Raw Data'!M15/'Raw Data'!N15 | K15: =IF('Raw Data'!F15=0,NA(),'Raw Data'!W15/'Raw Data'!F15) | L15: ='Raw Data'!Z15/'Raw Data'!AA15
A16: ='Raw Data'!A16 | B16: ='Raw Data'!B16 | C16: ='Raw Data'!J16/'Raw Data'!Y16 | D16: ='Raw Data'!J16/'Raw Data'!N16 | E16: ='Raw Data'!J16/'Raw Data'!C16 | F16: ='Raw Data'!W16/'Raw Data'!C16 | G16: ='Raw Data'!C16/'Raw Data'!N16 | H16: ='Raw Data'!N16/'Raw Data'!Y16 | I16: ='Raw Data'!M16/'Raw Data'!Y16 | J16: ='Raw Data'!M16/'Raw Data'!N16 | K16: =IF('Raw Data'!F16=0,NA(),'Raw Data'!W16/'Raw Data'!F16) | L16: ='Raw Data'!Z16/'Raw Data'!AA16
A17: ='Raw Data'!A17 | B17: ='Raw Data'!B17 | C17: ='Raw Data'!J17/'Raw Data'!Y17 | D17: ='Raw Data'!J17/'Raw Data'!N17 | E17: ='Raw Data'!J17/'Raw Data'!C17 | F17: ='Raw Data'!W17/'Raw Data'!C17 | G17: ='Raw Data'!C17/'Raw Data'!N17 | H17: ='Raw Data'!N17/'Raw Data'!Y17 | I17: ='Raw Data'!M17/'Raw Data'!Y17 | J17: ='Raw Data'!M17/'Raw Data'!N17 | K17: =IF('Raw Data'!F17=0,NA(),'Raw Data'!W17/'Raw Data'!F17) | L17: ='Raw Data'!Z17/'Raw Data'!AA17
A18: ='Raw Data'!A18 | B18: ='Raw Data'!B18 | C18: ='Raw Data'!J18/'Raw Data'!Y18 | D18: ='Raw Data'!J18/'Raw Data'!N18 | E18: ='Raw Data'!J18/'Raw Data'!C18 | F18: ='Raw Data'!W18/'Raw Data'!C18 | G18: ='Raw Data'!C18/'Raw Data'!N18 | H18: ='Raw Data'!N18/'Raw Data'!Y18 | I18: ='Raw Data'!M18/'Raw Data'!Y18 | J18: ='Raw Data'!M18/'Raw Data'!N18 | K18: =IF('Raw Data'!F18=0,NA(),'Raw Data'!W18/'Raw Data'!F18) | L18: ='Raw Data'!Z18/'Raw Data'!AA18
A19: ='Raw Data'!A19 | B19: ='Raw Data'!B19 | C19: ='Raw Data'!J19/'Raw Data'!Y19 | D19: ='Raw Data'!J19/'Raw Data'!N19 | E19: ='Raw Data'!J19/'Raw Data'!C19 | F19: ='Raw Data'!W19/'Raw Data'!C19 | G19: ='Raw Data'!C19/'Raw Data'!N19 | H19: ='Raw Data'!N19/'Raw Data'!Y19 | I19: ='Raw Data'!M19/'Raw Data'!Y19 | J19: ='Raw Data'!M19/'Raw Data'!N19 | K19: =IF('Raw Data'!F19=0,NA(),'Raw Data'!W19/'Raw Data'!F19) | L19: ='Raw Data'!Z19/'Raw Data'!AA19
... A41: ='Raw Data'!A41 | B41: ='Raw Data'!B41 | C41: ='Raw Data'!J41/'Raw Data'!Y41 | D41: ='Raw Data'!J41/'Raw Data'!N41 | E41: ='Raw Data'!J41/'Raw Data'!C41 | F41: ='Raw Data'!W41/'Raw Data'!C41 | G41: ='Raw Data'!C41/'Raw Data'!N41 | H41: ='Raw Data'!N41/'Raw Data'!Y41 | I41: ='Raw Data'!M41/'Raw Data'!Y41 | J41: ='Raw Data'!M41/'Raw Data'!N41 | K41: =IF('Raw Data'!F41=0,NA(),'Raw Data'!W41/'Raw Data'!F41) | L41: ='Raw Data'!Z41/'Raw Data'!AA41
A43: Every cell is a live formula into Raw Data. InterestCoverage is #N/A when InterestExpense = 0. CurrentRatio uses the schedule-based approximations (see Raw Data note).

Sheet DuPont Analysis
A1: Company | B1: Year | C1: TaxBurden NI/PBT | D1: IntBurden PBT/EBIT | E1: EBITMargin EBIT/Rev | F1: AssetTurn Rev/Assets | G1: EqMult Assets/Equity | H1: DuPont ROE | I1: Reported ROE | J1: Check | L1: ln-contributions (latest FY)
A2: ='Raw Data'!A2 | B2: ='Raw Data'!B2 | C2: ='Raw Data'!J2/'Raw Data'!H2 | D2: ='Raw Data'!H2/'Raw Data'!W2 | E2: ='Raw Data'!W2/'Raw Data'!C2 | F2: ='Raw Data'!C2/'Raw Data'!N2 | G2: ='Raw Data'!N2/'Raw Data'!Y2 | H2: =C2*D2*E2*F2*G2 | I2: ='Ratio Analysis'!C2 | J2: =IF(ABS(H2-I2)<0.0001,"✓","⚠") | L2: Firm | M2: TaxBurden | N2: IntBurden | O2: EBITMargin | P2: AssetTurn | Q2: EqMult
A3: ='Raw Data'!A3 | B3: ='Raw Data'!B3 | C3: ='Raw Data'!J3/'Raw Data'!H3 | D3: ='Raw Data'!H3/'Raw Data'!W3 | E3: ='Raw Data'!W3/'Raw Data'!C3 | F3: ='Raw Data'!C3/'Raw Data'!N3 | G3: ='Raw Data'!N3/'Raw Data'!Y3 | H3: =C3*D3*E3*F3*G3 | I3: ='Ratio Analysis'!C3 | J3: =IF(ABS(H3-I3)<0.0001,"✓","⚠") | L3: ='Raw Data'!A6 | M3: =LN(C6) | N3: =LN(D6) | O3: =LN(E6) | P3: =LN(F6) | Q3: =LN(G6)
A4: ='Raw Data'!A4 | B4: ='Raw Data'!B4 | C4: ='Raw Data'!J4/'Raw Data'!H4 | D4: ='Raw Data'!H4/'Raw Data'!W4 | E4: ='Raw Data'!W4/'Raw Data'!C4 | F4: ='Raw Data'!C4/'Raw Data'!N4 | G4: ='Raw Data'!N4/'Raw Data'!Y4 | H4: =C4*D4*E4*F4*G4 | I4: ='Ratio Analysis'!C4 | J4: =IF(ABS(H4-I4)<0.0001,"✓","⚠") | L4: ='Raw Data'!A11 | M4: =LN(C11) | N4: =LN(D11) | O4: =LN(E11) | P4: =LN(F11) | Q4: =LN(G11)
A5: ='Raw Data'!A5 | B5: ='Raw Data'!B5 | C5: ='Raw Data'!J5/'Raw Data'!H5 | D5: ='Raw Data'!H5/'Raw Data'!W5 | E5: ='Raw Data'!W5/'Raw Data'!C5 | F5: ='Raw Data'!C5/'Raw Data'!N5 | G5: ='Raw Data'!N5/'Raw Data'!Y5 | H5: =C5*D5*E5*F5*G5 | I5: ='Ratio Analysis'!C5 | J5: =IF(ABS(H5-I5)<0.0001,"✓","⚠") | L5: ='Raw Data'!A16 | M5: =LN(C16) | N5: =LN(D16) | O5: =LN(E16) | P5: =LN(F16) | Q5: =LN(G16)
A6: ='Raw Data'!A6 | B6: ='Raw Data'!B6 | C6: ='Raw Data'!J6/'Raw Data'!H6 | D6: ='Raw Data'!H6/'Raw Data'!W6 | E6: ='Raw Data'!W6/'Raw Data'!C6 | F6: ='Raw Data'!C6/'Raw Data'!N6 | G6: ='Raw Data'!N6/'Raw Data'!Y6 | H6: =C6*D6*E6*F6*G6 | I6: ='Ratio Analysis'!C6 | J6: =IF(ABS(H6-I6)<0.0001,"✓","⚠") | L6: ='Raw Data'!A21 | M6: =LN(C21) | N6: =LN(D21) | O6: =LN(E21) | P6: =LN(F21) | Q6: =LN(G21)
A7: ='Raw Data'!A7 | B7: ='Raw Data'!B7 | C7: ='Raw Data'!J7/'Raw Data'!H7 | D7: ='Raw Data'!H7/'Raw Data'!W7 | E7: ='Raw Data'!W7/'Raw Data'!C7 | F7: ='Raw Data'!C7/'Raw Data'!N7 | G7: ='Raw Data'!N7/'Raw Data'!Y7 | H7: =C7*D7*E7*F7*G7 | I7: ='Ratio Analysis'!C7 | J7: =IF(ABS(H7-I7)<0.0001,"✓","⚠") | L7: ='Raw Data'!A26 | M7: =LN(C26) | N7: =LN(D26) | O7: =LN(E26) | P7: =LN(F26) | Q7: =LN(G26)
A8: ='Raw Data'!A8 | B8: ='Raw Data'!B8 | C8: ='Raw Data'!J8/'Raw Data'!H8 | D8: ='Raw Data'!H8/'Raw Data'!W8 | E8: ='Raw Data'!W8/'Raw Data'!C8 | F8: ='Raw Data'!C8/'Raw Data'!N8 | G8: ='Raw Data'!N8/'Raw Data'!Y8 | H8: =C8*D8*E8*F8*G8 | I8: ='Ratio Analysis'!C8 | J8: =IF(ABS(H8-I8)<0.0001,"✓","⚠") | L8: ='Raw Data'!A31 | M8: =LN(C31) | N8: =LN(D31) | O8: =LN(E31) | P8: =LN(F31) | Q8: =LN(G31)
A9: ='Raw Data'!A9 | B9: ='Raw Data'!B9 | C9: ='Raw Data'!J9/'Raw Data'!H9 | D9: ='Raw Data'!H9/'Raw Data'!W9 | E9: ='Raw Data'!W9/'Raw Data'!C9 | F9: ='Raw Data'!C9/'Raw Data'!N9 | G9: ='Raw Data'!N9/'Raw Data'!Y9 | H9: =C9*D9*E9*F9*G9 | I9: ='Ratio Analysis'!C9 | J9: =IF(ABS(H9-I9)<0.0001,"✓","⚠") | L9: ='Raw Data'!A36 | M9: =LN(C36) | N9: =LN(D36) | O9: =LN(E36) | P9: =LN(F36) | Q9: =LN(G36)
A10: ='Raw Data'!A10 | B10: ='Raw Data'!B10 | C10: ='Raw Data'!J10/'Raw Data'!H10 | D10: ='Raw Data'!H10/'Raw Data'!W10 | E10: ='Raw Data'!W10/'Raw Data'!C10 | F10: ='Raw Data'!C10/'Raw Data'!N10 | G10: ='Raw Data'!N10/'Raw Data'!Y10 | H10: =C10*D10*E10*F10*G10 | I10: ='Ratio Analysis'!C10 | J10: =IF(ABS(H10-I10)<0.0001,"✓","⚠") | L10: ='Raw Data'!A41 | M10: =LN(C41) | N10: =LN(D41) | O10: =LN(E41) | P10: =LN(F41) | Q10: =LN(G41)
A11: ='Raw Data'!A11 | B11: ='Raw Data'!B11 | C11: ='Raw Data'!J11/'Raw Data'!H11 | D11: ='Raw Data'!H11/'Raw Data'!W11 | E11: ='Raw Data'!W11/'Raw Data'!C11 | F11: ='Raw Data'!C11/'Raw Data'!N11 | G11: ='Raw Data'!N11/'Raw Data'!Y11 | H11: =C11*D11*E11*F11*G11 | I11: ='Ratio Analysis'!C11 | J11: =IF(ABS(H11-I11)<0.0001,"✓","⚠")
A12: ='Raw Data'!A12 | B12: ='Raw Data'!B12 | C12: ='Raw Data'!J12/'Raw Data'!H12 | D12: ='Raw Data'!H12/'Raw Data'!W12 | E12: ='Raw Data'!W12/'Raw Data'!C12 | F12: ='Raw Data'!C12/'Raw Data'!N12 | G12: ='Raw Data'!N12/'Raw Data'!Y12 | H12: =C12*D12*E12*F12*G12 | I12: ='Ratio Analysis'!C12 | J12: =IF(ABS(H12-I12)<0.0001,"✓","⚠")
A13: ='Raw Data'!A13 | B13: ='Raw Data'!B13 | C13: ='Raw Data'!J13/'Raw Data'!H13 | D13: ='Raw Data'!H13/'Raw Data'!W13 | E13: ='Raw Data'!W13/'Raw Data'!C13 | F13: ='Raw Data'!C13/'Raw Data'!N13 | G13: ='Raw Data'!N13/'Raw Data'!Y13 | H13: =C13*D13*E13*F13*G13 | I13: ='Ratio Analysis'!C13 | J13: =IF(ABS(H13-I13)<0.0001,"✓","⚠")
A14: ='Raw Data'!A14 | B14: ='Raw Data'!B14 | C14: ='Raw Data'!J14/'Raw Data'!H14 | D14: ='Raw Data'!H14/'Raw Data'!W14 | E14: ='Raw Data'!W14/'Raw Data'!C14 | F14: ='Raw Data'!C14/'Raw Data'!N14 | G14: ='Raw Data'!N14/'Raw Data'!Y14 | H14: =C14*D14*E14*F14*G14 | I14: ='Ratio Analysis'!C14 | J14: =IF(ABS(H14-I14)<0.0001,"✓","⚠")
A15: ='Raw Data'!A15 | B15: ='Raw Data'!B15 | C15: ='Raw Data'!J15/'Raw Data'!H15 | D15: ='Raw Data'!H15/'Raw Data'!W15 | E15: ='Raw Data'!W15/'Raw Data'!C15 | F15: ='Raw Data'!C15/'Raw Data'!N15 | G15: ='Raw Data'!N15/'Raw Data'!Y15 | H15: =C15*D15*E15*F15*G15 | I15: ='Ratio Analysis'!C15 | J15: =IF(ABS(H15-I15)<0.0001,"✓","⚠")
A16: ='Raw Data'!A16 | B16: ='Raw Data'!B16 | C16: ='Raw Data'!J16/'Raw Data'!H16 | D16: ='Raw Data'!H16/'Raw Data'!W16 | E16: ='Raw Data'!W16/'Raw Data'!C16 | F16: ='Raw Data'!C16/'Raw Data'!N16 | G16: ='Raw Data'!N16/'Raw Data'!Y16 | H16: =C16*D16*E16*F16*G16 | I16: ='Ratio Analysis'!C16 | J16: =IF(ABS(H16-I16)<0.0001,"✓","⚠")
A17: ='Raw Data'!A17 | B17: ='Raw Data'!B17 | C17: ='Raw Data'!J17/'Raw Data'!H17 | D17: ='Raw Data'!H17/'Raw Data'!W17 | E17: ='Raw Data'!W17/'Raw Data'!C17 | F17: ='Raw Data'!C17/'Raw Data'!N17 | G17: ='Raw Data'!N17/'Raw Data'!Y17 | H17: =C17*D17*E17*F17*G17 | I17: ='Ratio Analysis'!C17 | J17: =IF(ABS(H17-I17)<0.0001,"✓","⚠")
A18: ='Raw Data'!A18 | B18: ='Raw Data'!B18 | C18: ='Raw Data'!J18/'Raw Data'!H18 | D18: ='Raw Data'!H18/'Raw Data'!W18 | E18: ='Raw Data'!W18/'Raw Data'!C18 | F18: ='Raw Data'!C18/'Raw Data'!N18 | G18: ='Raw Data'!N18/'Raw Data'!Y18 | H18: =C18*D18*E18*F18*G18 | I18: ='Ratio Analysis'!C18 | J18: =IF(ABS(H18-I18)<0.0001,"✓","⚠")
A19: ='Raw Data'!A19 | B19: ='Raw Data'!B19 | C19: ='Raw Data'!J19/'Raw Data'!H19 | D19: ='Raw Data'!H19/'Raw Data'!W19 | E19: ='Raw Data'!W19/'Raw Data'!C19 | F19: ='Raw Data'!C19/'Raw Data'!N19 | G19: ='Raw Data'!N19/'Raw Data'!Y19 | H19: =C19*D19*E19*F19*G19 | I19: ='Ratio Analysis'!C19 | J19: =IF(ABS(H19-I19)<0.0001,"✓","⚠")
A20: ='Raw Data'!A20 | B20: ='Raw Data'!B20 | C20: ='Raw Data'!J20/'Raw Data'!H20 | D20: ='Raw Data'!H20/'Raw Data'!W20 | E20: ='Raw Data'!W20/'Raw Data'!C20 | F20: ='Raw Data'!C20/'Raw Data'!N20 | G20: ='Raw Data'!N20/'Raw Data'!Y20 | H20: =C20*D20*E20*F20*G20 | I20: ='Ratio Analysis'!C20 | J20: =IF(ABS(H20-I20)<0.0001,"✓","⚠")
A21: ='Raw Data'!A21 | B21: ='Raw Data'!B21 | C21: ='Raw Data'!J21/'Raw Data'!H21 | D21: ='Raw Data'!H21/'Raw Data'!W21 | E21: ='Raw Data'!W21/'Raw Data'!C21 | F21: ='Raw Data'!C21/'Raw Data'!N21 | G21: ='Raw Data'!N21/'Raw Data'!Y21 | H21: =C21*D21*E21*F21*G21 | I21: ='Ratio Analysis'!C21 | J21: =IF(ABS(H21-I21)<0.0001,"✓","⚠")
A22: ='Raw Data'!A22 | B22: ='Raw Data'!B22 | C22: ='Raw Data'!J22/'Raw Data'!H22 | D22: ='Raw Data'!H22/'Raw Data'!W22 | E22: ='Raw Data'!W22/'Raw Data'!C22 | F22: ='Raw Data'!C22/'Raw Data'!N22 | G22: ='Raw Data'!N22/'Raw Data'!Y22 | H22: =C22*D22*E22*F22*G22 | I22: ='Ratio Analysis'!C22 | J22: =IF(ABS(H22-I22)<0.0001,"✓","⚠")
... A41: ='Raw Data'!A41 | B41: ='Raw Data'!B41 | C41: ='Raw Data'!J41/'Raw Data'!H41 | D41: ='Raw Data'!H41/'Raw Data'!W41 | E41: ='Raw Data'!W41/'Raw Data'!C41 | F41: ='Raw Data'!C41/'Raw Data'!N41 | G41: ='Raw Data'!N41/'Raw Data'!Y41 | H41: =C41*D41*E41*F41*G41 | I41: ='Ratio Analysis'!C41 | J41: =IF(ABS(H41-I41)<0.0001,"✓","⚠")
A43: 5-step DuPont: ROE = TaxBurden × IntBurden × EBITMargin × AssetTurnover × EqMultiplier. EBIT = PBT + Interest, so the identity is exact — Check must read ✓ on every row. Segments below zero in the chart (ln of components < 1) drag ROE down.

Sheet Capital Structure
A1: Company | B1: Year | C1: DebtToEquity | D1: DebtRatio | E1: InterestCoverage | F1: Band | H1: band edges | K1: D/E pivot
A2: ='Raw Data'!A2 | B2: ='Raw Data'!B2 | C2: ='Raw Data'!M2/'Raw Data'!Y2 | D2: ='Raw Data'!M2/'Raw Data'!N2 | E2: =IF('Raw Data'!F2=0,NA(),'Raw Data'!W2/'Raw Data'!F2) | F2: =IF(C2<$I$2,"Low",IF(C2<=$I$3,"Mid","High")) | H2: Low ≤ | I2: 0.3 | L2: ='Raw Data'!A2 | M2: ='Raw Data'!A7 | N2: ='Raw Data'!A12 | O2: ='Raw Data'!A17 | P2: ='Raw Data'!A22 | Q2: ='Raw Data'!A27 | R2: ='Raw Data'!A32 | S2: ='Raw Data'!A37
A3: ='Raw Data'!A3 | B3: ='Raw Data'!B3 | C3: ='Raw Data'!M3/'Raw Data'!Y3 | D3: ='Raw Data'!M3/'Raw Data'!N3 | E3: =IF('Raw Data'!F3=0,NA(),'Raw Data'!W3/'Raw Data'!F3) | F3: =IF(C3<$I$2,"Low",IF(C3<=$I$3,"Mid","High")) | H3: Mid ≤ | I3: 0.7 | K3: FY2022 | L3: =C2 | M3: =C7 | N3: =C12 | O3: =C17 | P3: =C22 | Q3: =C27 | R3: =C32 | S3: =C37
A4: ='Raw Data'!A4 | B4: ='Raw Data'!B4 | C4: ='Raw Data'!M4/'Raw Data'!Y4 | D4: ='Raw Data'!M4/'Raw Data'!N4 | E4: =IF('Raw Data'!F4=0,NA(),'Raw Data'!W4/'Raw Data'!F4) | F4: =IF(C4<$I$2,"Low",IF(C4<=$I$3,"Mid","High")) | K4: FY2023 | L4: =C3 | M4: =C8 | N4: =C13 | O4: =C18 | P4: =C23 | Q4: =C28 | R4: =C33 | S4: =C38
A5: ='Raw Data'!A5 | B5: ='Raw Data'!B5 | C5: ='Raw Data'!M5/'Raw Data'!Y5 | D5: ='Raw Data'!M5/'Raw Data'!N5 | E5: =IF('Raw Data'!F5=0,NA(),'Raw Data'!W5/'Raw Data'!F5) | F5: =IF(C5<$I$2,"Low",IF(C5<=$I$3,"Mid","High")) | K5: FY2024 | L5: =C4 | M5: =C9 | N5: =C14 | O5: =C19 | P5: =C24 | Q5: =C29 | R5: =C34 | S5: =C39
A6: ='Raw Data'!A6 | B6: ='Raw Data'!B6 | C6: ='Raw Data'!M6/'Raw Data'!Y6 | D6: ='Raw Data'!M6/'Raw Data'!N6 | E6: =IF('Raw Data'!F6=0,NA(),'Raw Data'!W6/'Raw Data'!F6) | F6: =IF(C6<$I$2,"Low",IF(C6<=$I$3,"Mid","High")) | K6: FY2025 | L6: =C5 | M6: =C10 | N6: =C15 | O6: =C20 | P6: =C25 | Q6: =C30 | R6: =C35 | S6: =C40
A7: ='Raw Data'!A7 | B7: ='Raw Data'!B7 | C7: ='Raw Data'!M7/'Raw Data'!Y7 | D7: ='Raw Data'!M7/'Raw Data'!N7 | E7: =IF('Raw Data'!F7=0,NA(),'Raw Data'!W7/'Raw Data'!F7) | F7: =IF(C7<$I$2,"Low",IF(C7<=$I$3,"Mid","High")) | K7: FY2026 | L7: =C6 | M7: =C11 | N7: =C16 | O7: =C21 | P7: =C26 | Q7: =C31 | R7: =C36 | S7: =C41
A8: ='Raw Data'!A8 | B8: ='Raw Data'!B8 | C8: ='Raw Data'!M8/'Raw Data'!Y8 | D8: ='Raw Data'!M8/'Raw Data'!N8 | E8: =IF('Raw Data'!F8=0,NA(),'Raw Data'!W8/'Raw Data'!F8) | F8: =IF(C8<$I$2,"Low",IF(C8<=$I$3,"Mid","High"))
A9: ='Raw Data'!A9 | B9: ='Raw Data'!B9 | C9: ='Raw Data'!M9/'Raw Data'!Y9 | D9: ='Raw Data'!M9/'Raw Data'!N9 | E9: =IF('Raw Data'!F9=0,NA(),'Raw Data'!W9/'Raw Data'!F9) | F9: =IF(C9<$I$2,"Low",IF(C9<=$I$3,"Mid","High"))
A10: ='Raw Data'!A10 | B10: ='Raw Data'!B10 | C10: ='Raw Data'!M10/'Raw Data'!Y10 | D10: ='Raw Data'!M10/'Raw Data'!N10 | E10: =IF('Raw Data'!F10=0,NA(),'Raw Data'!W10/'Raw Data'!F10) | F10: =IF(C10<$I$2,"Low",IF(C10<=$I$3,"Mid","High")) | K10: InterestCoverage pivot
A11: ='Raw Data'!A11 | B11: ='Raw Data'!B11 | C11: ='Raw Data'!M11/'Raw Data'!Y11 | D11: ='Raw Data'!M11/'Raw Data'!N11 | E11: =IF('Raw Data'!F11=0,NA(),'Raw Data'!W11/'Raw Data'!F11) | F11: =IF(C11<$I$2,"Low",IF(C11<=$I$3,"Mid","High")) | L11: ='Raw Data'!A2 | M11: ='Raw Data'!A7 | N11: ='Raw Data'!A12 | O11: ='Raw Data'!A17 | P11: ='Raw Data'!A22 | Q11: ='Raw Data'!A27 | R11: ='Raw Data'!A32 | S11: ='Raw Data'!A37
A12: ='Raw Data'!A12 | B12: ='Raw Data'!B12 | C12: ='Raw Data'!M12/'Raw Data'!Y12 | D12: ='Raw Data'!M12/'Raw Data'!N12 | E12: =IF('Raw Data'!F12=0,NA(),'Raw Data'!W12/'Raw Data'!F12) | F12: =IF(C12<$I$2,"Low",IF(C12<=$I$3,"Mid","High")) | K12: FY2022 | L12: =E2 | M12: =E7 | N12: =E12 | O12: =E17 | P12: =E22 | Q12: =E27 | R12: =E32 | S12: =E37
A13: ='Raw Data'!A13 | B13: ='Raw Data'!B13 | C13: ='Raw Data'!M13/'Raw Data'!Y13 | D13: ='Raw Data'!M13/'Raw Data'!N13 | E13: =IF('Raw Data'!F13=0,NA(),'Raw Data'!W13/'Raw Data'!F13) | F13: =IF(C13<$I$2,"Low",IF(C13<=$I$3,"Mid","High")) | K13: FY2023 | L13: =E3 | M13: =E8 | N13: =E13 | O13: =E18 | P13: =E23 | Q13: =E28 | R13: =E33 | S13: =E38
A14: ='Raw Data'!A14 | B14: ='Raw Data'!B14 | C14: ='Raw Data'!M14/'Raw Data'!Y14 | D14: ='Raw Data'!M14/'Raw Data'!N14 | E14: =IF('Raw Data'!F14=0,NA(),'Raw Data'!W14/'Raw Data'!F14) | F14: =IF(C14<$I$2,"Low",IF(C14<=$I$3,"Mid","High")) | K14: FY2024 | L14: =E4 | M14: =E9 | N14: =E14 | O14: =E19 | P14: =E24 | Q14: =E29 | R14: =E34 | S14: =E39
A15: ='Raw Data'!A15 | B15: ='Raw Data'!B15 | C15: ='Raw Data'!M15/'Raw Data'!Y15 | D15: ='Raw Data'!M15/'Raw Data'!N15 | E15: =IF('Raw Data'!F15=0,NA(),'Raw Data'!W15/'Raw Data'!F15) | F15: =IF(C15<$I$2,"Low",IF(C15<=$I$3,"Mid","High")) | K15: FY2025 | L15: =E5 | M15: =E10 | N15: =E15 | O15: =E20 | P15: =E25 | Q15: =E30 | R15: =E35 | S15: =E40
A16: ='Raw Data'!A16 | B16: ='Raw Data'!B16 | C16: ='Raw Data'!M16/'Raw Data'!Y16 | D16: ='Raw Data'!M16/'Raw Data'!N16 | E16: =IF('Raw Data'!F16=0,NA(),'Raw Data'!W16/'Raw Data'!F16) | F16: =IF(C16<$I$2,"Low",IF(C16<=$I$3,"Mid","High")) | K16: FY2026 | L16: =E6 | M16: =E11 | N16: =E16 | O16: =E21 | P16: =E26 | Q16: =E31 | R16: =E36 | S16: =E41
A17: ='Raw Data'!A17 | B17: ='Raw Data'!B17 | C17: ='Raw Data'!M17/'Raw Data'!Y17 | D17: ='Raw Data'!M17/'Raw Data'!N17 | E17: =IF('Raw Data'!F17=0,NA(),'Raw Data'!W17/'Raw Data'!F17) | F17: =IF(C17<$I$2,"Low",IF(C17<=$I$3,"Mid","High"))
A18: ='Raw Data'!A18 | B18: ='Raw Data'!B18 | C18: ='Raw Data'!M18/'Raw Data'!Y18 | D18: ='Raw Data'!M18/'Raw Data'!N18 | E18: =IF('Raw Data'!F18=0,NA(),'Raw Data'!W18/'Raw Data'!F18) | F18: =IF(C18<$I$2,"Low",IF(C18<=$I$3,"Mid","High"))
A19: ='Raw Data'!A19 | B19: ='Raw Data'!B19 | C19: ='Raw Data'!M19/'Raw Data'!Y19 | D19: ='Raw Data'!M19/'Raw Data'!N19 | E19: =IF('Raw Data'!F19=0,NA(),'Raw Data'!W19/'Raw Data'!F19) | F19: =IF(C19<$I$2,"Low",IF(C19<=$I$3,"Mid","High"))
A20: ='Raw Data'!A20 | B20: ='Raw Data'!B20 | C20: ='Raw Data'!M20/'Raw Data'!Y20 | D20: ='Raw Data'!M20/'Raw Data'!N20 | E20: =IF('Raw Data'!F20=0,NA(),'Raw Data'!W20/'Raw Data'!F20) | F20: =IF(C20<$I$2,"Low",IF(C20<=$I$3,"Mid","High"))
A21: ='Raw Data'!A21 | B21: ='Raw Data'!B21 | C21: ='Raw Data'!M21/'Raw Data'!Y21 | D21: ='Raw Data'!M21/'Raw Data'!N21 | E21: =IF('Raw Data'!F21=0,NA(),'Raw Data'!W21/'Raw Data'!F21) | F21: =IF(C21<$I$2,"Low",IF(C21<=$I$3,"Mid","High"))
A22: ='Raw Data'!A22 | B22: ='Raw Data'!B22 | C22: ='Raw Data'!M22/'Raw Data'!Y22 | D22: ='Raw Data'!M22/'Raw Data'!N22 | E22: =IF('Raw Data'!F22=0,NA(),'Raw Data'!W22/'Raw Data'!F22) | F22: =IF(C22<$I$2,"Low",IF(C22<=$I$3,"Mid","High"))
A23: ='Raw Data'!A23 | B23: ='Raw Data'!B23 | C23: ='Raw Data'!M23/'Raw Data'!Y23 | D23: ='Raw Data'!M23/'Raw Data'!N23 | E23: =IF('Raw Data'!F23=0,NA(),'Raw Data'!W23/'Raw Data'!F23) | F23: =IF(C23<$I$2,"Low",IF(C23<=$I$3,"Mid","High"))
A24: ='Raw Data'!A24 | B24: ='Raw Data'!B24 | C24: ='Raw Data'!M24/'Raw Data'!Y24 | D24: ='Raw Data'!M24/'Raw Data'!N24 | E24: =IF('Raw Data'!F24=0,NA(),'Raw Data'!W24/'Raw Data'!F24) | F24: =IF(C24<$I$2,"Low",IF(C24<=$I$3,"Mid","High"))
A25: ='Raw Data'!A25 | B25: ='Raw Data'!B25 | C25: ='Raw Data'!M25/'Raw Data'!Y25 | D25: ='Raw Data'!M25/'Raw Data'!N25 | E25: =IF('Raw Data'!F25=0,NA(),'Raw Data'!W25/'Raw Data'!F25) | F25: =IF(C25<$I$2,"Low",IF(C25<=$I$3,"Mid","High"))
A26: ='Raw Data'!A26 | B26: ='Raw Data'!B26 | C26: ='Raw Data'!M26/'Raw Data'!Y26 | D26: ='Raw Data'!M26/'Raw Data'!N26 | E26: =IF('Raw Data'!F26=0,NA(),'Raw Data'!W26/'Raw Data'!F26) | F26: =IF(C26<$I$2,"Low",IF(C26<=$I$3,"Mid","High"))
A27: ='Raw Data'!A27 | B27: ='Raw Data'!B27 | C27: ='Raw Data'!M27/'Raw Data'!Y27 | D27: ='Raw Data'!M27/'Raw Data'!N27 | E27: =IF('Raw Data'!F27=0,NA(),'Raw Data'!W27/'Raw Data'!F27) | F27: =IF(C27<$I$2,"Low",IF(C27<=$I$3,"Mid","High"))
A28: ='Raw Data'!A28 | B28: ='Raw Data'!B28 | C28: ='Raw Data'!M28/'Raw Data'!Y28 | D28: ='Raw Data'!M28/'Raw Data'!N28 | E28: =IF('Raw Data'!F28=0,NA(),'Raw Data'!W28/'Raw Data'!F28) | F28: =IF(C28<$I$2,"Low",IF(C28<=$I$3,"Mid","High"))
... A41: ='Raw Data'!A41 | B41: ='Raw Data'!B41 | C41: ='Raw Data'!M41/'Raw Data'!Y41 | D41: ='Raw Data'!M41/'Raw Data'!N41 | E41: =IF('Raw Data'!F41=0,NA(),'Raw Data'!W41/'Raw Data'!F41) | F41: =IF(C41<$I$2,"Low",IF(C41<=$I$3,"Mid","High"))
A43: Band = IF(D/E < edge1, Low, IF(≤ edge2, Mid, High)) — edges are the yellow cells, change them and the classification recomputes. This universe is structurally low-leverage.

Sheet Leverage Threshold
A1: Leverage threshold — where does ROE peak across D/E?
A2: bin table computed in python (leverage_threshold.py) on the live ratio panel · scatter is formula-driven off the sheets
A4: Method | B4: Bin | C4: DE_low | D4: DE_high | E4: MeanROE | F4: MeanNetMargin | G4: N
A5: Band | B5: Low | C5: 0.0023 | D5: 0.2835 | E5: 0.41751912 | F5: 0.20892741 | G5: 38 | H5: ← peak ROE
A6: Band | B6: Mid | C6: 0.3163 | D6: 0.3758 | E6: 0.17738751 | F6: 0.15582214 | G6: 2
A7: Quintile | B7: (0.00131, 0.00927] | C7: 0.0023 | D7: 0.0092 | E7: 0.28297954 | F7: 0.28841903 | G7: 8
A8: Quintile | B8: (0.00927, 0.031] | C8: 0.0093 | D8: 0.0309 | E8: 0.31724356 | F8: 0.21649188 | G8: 8
A9: Quintile | B9: (0.031, 0.0534] | C9: 0.031 | D9: 0.0511 | E9: 0.4827884 | F9: 0.19748366 | G9: 8
A10: Quintile | B10: (0.0534, 0.104] | C10: 0.0569 | D10: 0.1033 | E10: 0.43885226 | F10: 0.16485194 | G10: 8
A11: Quintile | B11: (0.104, 0.376] | C11: 0.1074 | D11: 0.3758 | E11: 0.50569895 | F11: 0.16411424 | G11: 8 | H11: ← peak ROE
A12: Decile | B12: (0.00131, 0.00487] | C12: 0.0023 | D12: 0.0048 | E12: 0.31674054 | F12: 0.3326207 | G12: 4
A13: Decile | B13: (0.00487, 0.00927] | C13: 0.0049 | D13: 0.0092 | E13: 0.24921853 | F13: 0.24421735 | G13: 4
A14: Decile | B14: (0.00927, 0.0269] | C14: 0.0093 | D14: 0.0269 | E14: 0.23653804 | F14: 0.19676596 | G14: 4
A15: Decile | B15: (0.0269, 0.031] | C15: 0.027 | D15: 0.0309 | E15: 0.39794908 | F15: 0.2362178 | G15: 4
A16: Decile | B16: (0.031, 0.0393] | C16: 0.031 | D16: 0.0384 | E16: 0.5302086 | F16: 0.21395527 | G16: 4
A17: Decile | B17: (0.0393, 0.0534] | C17: 0.0402 | D17: 0.0511 | E17: 0.4353682 | F17: 0.18101205 | G17: 4
A18: Decile | B18: (0.0534, 0.0819] | C18: 0.0569 | D18: 0.0812 | E18: 0.30069488 | F18: 0.1677996 | G18: 4
A19: Decile | B19: (0.0819, 0.104] | C19: 0.0836 | D19: 0.1033 | E19: 0.57700963 | F19: 0.16190427 | G19: 4
A20: Decile | B20: (0.104, 0.122] | C20: 0.1074 | D20: 0.1122 | E20: 0.70453175 | F20: 0.19007584 | G20: 4 | H20: ← peak ROE
A21: Decile | B21: (0.122, 0.376] | C21: 0.2103 | D21: 0.3758 | E21: 0.30686615 | F21: 0.13815263 | G21: 4
A23: Finding: average ROE peaks at 70% in the D/E 0.11–0.11 decile, then falls to 31% in the top decile (D/E 0.21–0.38) — an inverted-U inside a low-leverage sector.

Sheet WACC
A1: WACC — CAPM cost of equity + clamped cost of debt
A2: yellow = assumptions to challenge · every other cell recalculates from Raw Data / Market Data
A4: Risk-free rate (10Y G-Sec) | B4: 0.07
A5: Equity risk premium (India) | B5: 0.055
A6: Kd clamp low (Rf - 2%) | B6: =B4-0.02
A7: Kd clamp high (Rf + 6%) | B7: =B4+0.06
A9: Company | B9: Beta | C9: Ke (CAPM) | D9: Debt latest | E9: Debt prior | F9: Interest | G9: Kd raw | H9: Kd used | I9: Tax (3y avg) | J9: E = MktCap | K9: V = E+D | L9: D/V | M9: WACC
A10: HUL | B10: 0.55 | C10: =$B$4+B10*$B$5 | D10: ='Raw Data'!M6 | E10: ='Raw Data'!U6 | F10: ='Raw Data'!F6 | G10: =IF((D10+E10)=0,NA(),F10/((D10+E10)/2)) | H10: =IF(ISNA(G10),$B$4+0.01,MIN(MAX(G10,$B$6),$B$7)) | I10: =AVERAGE('Raw Data'!V6,'Raw Data'!V5,'Raw Data'!V4) | J10: ='Market Data'!B2 | K10: =J10+D10 | L10: =D10/K10 | M10: =(J10/K10)*C10+(D10/K10)*H10*(1-I10)
A11: ITC | B11: 0.75 | C11: =$B$4+B11*$B$5 | D11: ='Raw Data'!M11 | E11: ='Raw Data'!U11 | F11: ='Raw Data'!F11 | G11: =IF((D11+E11)=0,NA(),F11/((D11+E11)/2)) | H11: =IF(ISNA(G11),$B$4+0.01,MIN(MAX(G11,$B$6),$B$7)) | I11: =AVERAGE('Raw Data'!V11,'Raw Data'!V10,'Raw Data'!V9) | J11: ='Market Data'!B3 | K11: =J11+D11 | L11: =D11/K11 | M11: =(J11/K11)*C11+(D11/K11)*H11*(1-I11)
A12: Dabur | B12: 0.6 | C12: =$B$4+B12*$B$5 | D12: ='Raw Data'!M16 | E12: ='Raw Data'!U16 | F12: ='Raw Data'!F16 | G12: =IF((D12+E12)=0,NA(),F12/((D12+E12)/2)) | H12: =IF(ISNA(G12),$B$4+0.01,MIN(MAX(G12,$B$6),$B$7)) | I12: =AVERAGE('Raw Data'!V16,'Raw Data'!V15,'Raw Data'!V14) | J12: ='Market Data'!B4 | K12: =J12+D12 | L12: =D12/K12 | M12: =(J12/K12)*C12+(D12/K12)*H12*(1-I12)
A13: Marico | B13: 0.55 | C13: =$B$4+B13*$B$5 | D13: ='Raw Data'!M21 | E13: ='Raw Data'!U21 | F13: ='Raw Data'!F21 | G13: =IF((D13+E13)=0,NA(),F13/((D13+E13)/2)) | H13: =IF(ISNA(G13),$B$4+0.01,MIN(MAX(G13,$B$6),$B$7)) | I13: =AVERAGE('Raw Data'!V21,'Raw Data'!V20,'Raw Data'!V19) | J13: ='Market Data'!B5 | K13: =J13+D13 | L13: =D13/K13 | M13: =(J13/K13)*C13+(D13/K13)*H13*(1-I13)
A14: Colgate | B14: 0.65 | C14: =$B$4+B14*$B$5 | D14: ='Raw Data'!M26 | E14: ='Raw Data'!U26 | F14: ='Raw Data'!F26 | G14: =IF((D14+E14)=0,NA(),F14/((D14+E14)/2)) | H14: =IF(ISNA(G14),$B$4+0.01,MIN(MAX(G14,$B$6),$B$7)) | I14: =AVERAGE('Raw Data'!V26,'Raw Data'!V25,'Raw Data'!V24) | J14: ='Market Data'!B6 | K14: =J14+D14 | L14: =D14/K14 | M14: =(J14/K14)*C14+(D14/K14)*H14*(1-I14)
A15: Nestle | B15: 0.5 | C15: =$B$4+B15*$B$5 | D15: ='Raw Data'!M31 | E15: ='Raw Data'!U31 | F15: ='Raw Data'!F31 | G15: =IF((D15+E15)=0,NA(),F15/((D15+E15)/2)) | H15: =IF(ISNA(G15),$B$4+0.01,MIN(MAX(G15,$B$6),$B$7)) | I15: =AVERAGE('Raw Data'!V31,'Raw Data'!V30,'Raw Data'!V29) | J15: ='Market Data'!B7 | K15: =J15+D15 | L15: =D15/K15 | M15: =(J15/K15)*C15+(D15/K15)*H15*(1-I15)
A16: Godrej | B16: 0.7 | C16: =$B$4+B16*$B$5 | D16: ='Raw Data'!M36 | E16: ='Raw Data'!U36 | F16: ='Raw Data'!F36 | G16: =IF((D16+E16)=0,NA(),F16/((D16+E16)/2)) | H16: =IF(ISNA(G16),$B$4+0.01,MIN(MAX(G16,$B$6),$B$7)) | I16: =AVERAGE('Raw Data'!V36,'Raw Data'!V35,'Raw Data'!V34) | J16: ='Market Data'!B8 | K16: =J16+D16 | L16: =D16/K16 | M16: =(J16/K16)*C16+(D16/K16)*H16*(1-I16)
A17: Emami | B17: 0.65 | C17: =$B$4+B17*$B$5 | D17: ='Raw Data'!M41 | E17: ='Raw Data'!U41 | F17: ='Raw Data'!F41 | G17: =IF((D17+E17)=0,NA(),F17/((D17+E17)/2)) | H17: =IF(ISNA(G17),$B$4+0.01,MIN(MAX(G17,$B$6),$B$7)) | I17: =AVERAGE('Raw Data'!V41,'Raw Data'!V40,'Raw Data'!V39) | J17: ='Market Data'!B9 | K17: =J17+D17 | L17: =D17/K17 | M17: =(J17/K17)*C17+(D17/K17)*H17*(1-I17)
A19: Book-weight WACC per firm-year (equity at book value — shows the leverage-mix effect)
B20: FY2022 | C20: FY2023 | D20: FY2024 | E20: FY2025 | F20: FY2026
A21: HUL | B21: =('Raw Data'!Y2/('Raw Data'!Y2+'Raw Data'!M2))*$C$10+('Raw Data'!M2/('Raw Data'!Y2+'Raw Data'!M2))*$H$10*(1-'Raw Data'!V2) | C21: =('Raw Data'!Y3/('Raw Data'!Y3+'Raw Data'!M3))*$C$10+('Raw Data'!M3/('Raw Data'!Y3+'Raw Data'!M3))*$H$10*(1-'Raw Data'!V3) | D21: =('Raw Data'!Y4/('Raw Data'!Y4+'Raw Data'!M4))*$C$10+('Raw Data'!M4/('Raw Data'!Y4+'Raw Data'!M4))*$H$10*(1-'Raw Data'!V4) | E21: =('Raw Data'!Y5/('Raw Data'!Y5+'Raw Data'!M5))*$C$10+('Raw Data'!M5/('Raw Data'!Y5+'Raw Data'!M5))*$H$10*(1-'Raw Data'!V5) | F21: =('Raw Data'!Y6/('Raw Data'!Y6+'Raw Data'!M6))*$C$10+('Raw Data'!M6/('Raw Data'!Y6+'Raw Data'!M6))*$H$10*(1-'Raw Data'!V6)
A22: ITC | B22: =('Raw Data'!Y7/('Raw Data'!Y7+'Raw Data'!M7))*$C$11+('Raw Data'!M7/('Raw Data'!Y7+'Raw Data'!M7))*$H$11*(1-'Raw Data'!V7) | C22: =('Raw Data'!Y8/('Raw Data'!Y8+'Raw Data'!M8))*$C$11+('Raw Data'!M8/('Raw Data'!Y8+'Raw Data'!M8))*$H$11*(1-'Raw Data'!V8) | D22: =('Raw Data'!Y9/('Raw Data'!Y9+'Raw Data'!M9))*$C$11+('Raw Data'!M9/('Raw Data'!Y9+'Raw Data'!M9))*$H$11*(1-'Raw Data'!V9) | E22: =('Raw Data'!Y10/('Raw Data'!Y10+'Raw Data'!M10))*$C$11+('Raw Data'!M10/('Raw Data'!Y10+'Raw Data'!M10))*$H$11*(1-'Raw Data'!V10) | F22: =('Raw Data'!Y11/('Raw Data'!Y11+'Raw Data'!M11))*$C$11+('Raw Data'!M11/('Raw Data'!Y11+'Raw Data'!M11))*$H$11*(1-'Raw Data'!V11)
A23: Dabur | B23: =('Raw Data'!Y12/('Raw Data'!Y12+'Raw Data'!M12))*$C$12+('Raw Data'!M12/('Raw Data'!Y12+'Raw Data'!M12))*$H$12*(1-'Raw Data'!V12) | C23: =('Raw Data'!Y13/('Raw Data'!Y13+'Raw Data'!M13))*$C$12+('Raw Data'!M13/('Raw Data'!Y13+'Raw Data'!M13))*$H$12*(1-'Raw Data'!V13) | D23: =('Raw Data'!Y14/('Raw Data'!Y14+'Raw Data'!M14))*$C$12+('Raw Data'!M14/('Raw Data'!Y14+'Raw Data'!M14))*$H$12*(1-'Raw Data'!V14) | E23: =('Raw Data'!Y15/('Raw Data'!Y15+'Raw Data'!M15))*$C$12+('Raw Data'!M15/('Raw Data'!Y15+'Raw Data'!M15))*$H$12*(1-'Raw Data'!V15) | F23: =('Raw Data'!Y16/('Raw Data'!Y16+'Raw Data'!M16))*$C$12+('Raw Data'!M16/('Raw Data'!Y16+'Raw Data'!M16))*$H$12*(1-'Raw Data'!V16)
A24: Marico | B24: =('Raw Data'!Y17/('Raw Data'!Y17+'Raw Data'!M17))*$C$13+('Raw Data'!M17/('Raw Data'!Y17+'Raw Data'!M17))*$H$13*(1-'Raw Data'!V17) | C24: =('Raw Data'!Y18/('Raw Data'!Y18+'Raw Data'!M18))*$C$13+('Raw Data'!M18/('Raw Data'!Y18+'Raw Data'!M18))*$H$13*(1-'Raw Data'!V18) | D24: =('Raw Data'!Y19/('Raw Data'!Y19+'Raw Data'!M19))*$C$13+('Raw Data'!M19/('Raw Data'!Y19+'Raw Data'!M19))*$H$13*(1-'Raw Data'!V19) | E24: =('Raw Data'!Y20/('Raw Data'!Y20+'Raw Data'!M20))*$C$13+('Raw Data'!M20/('Raw Data'!Y20+'Raw Data'!M20))*$H$13*(1-'Raw Data'!V20) | F24: =('Raw Data'!Y21/('Raw Data'!Y21+'Raw Data'!M21))*$C$13+('Raw Data'!M21/('Raw Data'!Y21+'Raw Data'!M21))*$H$13*(1-'Raw Data'!V21)
A25: Colgate | B25: =('Raw Data'!Y22/('Raw Data'!Y22+'Raw Data'!M22))*$C$14+('Raw Data'!M22/('Raw Data'!Y22+'Raw Data'!M22))*$H$14*(1-'Raw Data'!V22) | C25: =('Raw Data'!Y23/('Raw Data'!Y23+'Raw Data'!M23))*$C$14+('Raw Data'!M23/('Raw Data'!Y23+'Raw Data'!M23))*$H$14*(1-'Raw Data'!V23) | D25: =('Raw Data'!Y24/('Raw Data'!Y24+'Raw Data'!M24))*$C$14+('Raw Data'!M24/('Raw Data'!Y24+'Raw Data'!M24))*$H$14*(1-'Raw Data'!V24) | E25: =('Raw Data'!Y25/('Raw Data'!Y25+'Raw Data'!M25))*$C$14+('Raw Data'!M25/('Raw Data'!Y25+'Raw Data'!M25))*$H$14*(1-'Raw Data'!V25) | F25: =('Raw Data'!Y26/('Raw Data'!Y26+'Raw Data'!M26))*$C$14+('Raw Data'!M26/('Raw Data'!Y26+'Raw Data'!M26))*$H$14*(1-'Raw Data'!V26)
A26: Nestle | B26: =('Raw Data'!Y27/('Raw Data'!Y27+'Raw Data'!M27))*$C$15+('Raw Data'!M27/('Raw Data'!Y27+'Raw Data'!M27))*$H$15*(1-'Raw Data'!V27) | C26: =('Raw Data'!Y28/('Raw Data'!Y28+'Raw Data'!M28))*$C$15+('Raw Data'!M28/('Raw Data'!Y28+'Raw Data'!M28))*$H$15*(1-'Raw Data'!V28) | D26: =('Raw Data'!Y29/('Raw Data'!Y29+'Raw Data'!M29))*$C$15+('Raw Data'!M29/('Raw Data'!Y29+'Raw Data'!M29))*$H$15*(1-'Raw Data'!V29) | E26: =('Raw Data'!Y30/('Raw Data'!Y30+'Raw Data'!M30))*$C$15+('Raw Data'!M30/('Raw Data'!Y30+'Raw Data'!M30))*$H$15*(1-'Raw Data'!V30) | F26: =('Raw Data'!Y31/('Raw Data'!Y31+'Raw Data'!M31))*$C$15+('Raw Data'!M31/('Raw Data'!Y31+'Raw Data'!M31))*$H$15*(1-'Raw Data'!V31)
A27: Godrej | B27: =('Raw Data'!Y32/('Raw Data'!Y32+'Raw Data'!M32))*$C$16+('Raw Data'!M32/('Raw Data'!Y32+'Raw Data'!M32))*$H$16*(1-'Raw Data'!V32) | C27: =('Raw Data'!Y33/('Raw Data'!Y33+'Raw Data'!M33))*$C$16+('Raw Data'!M33/('Raw Data'!Y33+'Raw Data'!M33))*$H$16*(1-'Raw Data'!V33) | D27: =('Raw Data'!Y34/('Raw Data'!Y34+'Raw Data'!M34))*$C$16+('Raw Data'!M34/('Raw Data'!Y34+'Raw Data'!M34))*$H$16*(1-'Raw Data'!V34) | E27: =('Raw Data'!Y35/('Raw Data'!Y35+'Raw Data'!M35))*$C$16+('Raw Data'!M35/('Raw Data'!Y35+'Raw Data'!M35))*$H$16*(1-'Raw Data'!V35) | F27: =('Raw Data'!Y36/('Raw Data'!Y36+'Raw Data'!M36))*$C$16+('Raw Data'!M36/('Raw Data'!Y36+'Raw Data'!M36))*$H$16*(1-'Raw Data'!V36)
A28: Emami | B28: =('Raw Data'!Y37/('Raw Data'!Y37+'Raw Data'!M37))*$C$17+('Raw Data'!M37/('Raw Data'!Y37+'Raw Data'!M37))*$H$17*(1-'Raw Data'!V37) | C28: =('Raw Data'!Y38/('Raw Data'!Y38+'Raw Data'!M38))*$C$17+('Raw Data'!M38/('Raw Data'!Y38+'Raw Data'!M38))*$H$17*(1-'Raw Data'!V38) | D28: =('Raw Data'!Y39/('Raw Data'!Y39+'Raw Data'!M39))*$C$17+('Raw Data'!M39/('Raw Data'!Y39+'Raw Data'!M39))*$H$17*(1-'Raw Data'!V39) | E28: =('Raw Data'!Y40/('Raw Data'!Y40+'Raw Data'!M40))*$C$17+('Raw Data'!M40/('Raw Data'!Y40+'Raw Data'!M40))*$H$17*(1-'Raw Data'!V40) | F28: =('Raw Data'!Y41/('Raw Data'!Y41+'Raw Data'!M41))*$C$17+('Raw Data'!M41/('Raw Data'!Y41+'Raw Data'!M41))*$H$17*(1-'Raw Data'!V41)
A30: Main table: market-value equity weights (feeds the DCF). Matrix: book weights per year — more debt in the mix lowers book WACC via the tax shield, until risk reprices Ke/Kd (not modelled by CAPM with a constant beta).

Sheet Correlation Matrix
A1: Ratio correlation matrix (Pearson, 40 firm-years)
A2: computed in python — correlation_matrix.py · heatmap: red −1 → white 0 → green +1
B4: ROE | C4: ROA | D4: NetMargin | E4: EBITMargin | F4: AssetTurnover | G4: EquityMultiplier | H4: DebtToEquity | I4: DebtRatio | J4: InterestCoverage | K4: CurrentRatio
A5: ROE | B5: 1 | C5: 0.78 | D5: 0.005 | E5: 0.039 | F5: 0.902 | G5: 0.846 | H5: 0.062 | I5: -0.175 | J5: 0.034 | K5: -0.133
A6: ROA | B6: 0.78 | C6: 1 | D6: 0.457 | E6: 0.429 | F6: 0.757 | G6: 0.343 | H6: -0.268 | I6: -0.39 | J6: 0.454 | K6: 0.366
A7: NetMargin | B7: 0.005 | C7: 0.457 | D7: 1 | E7: 0.932 | F7: -0.202 | G7: -0.347 | H7: -0.443 | I7: -0.42 | J7: 0.868 | K7: 0.451
A8: EBITMargin | B8: 0.039 | C8: 0.429 | D8: 0.932 | E8: 1 | F8: -0.187 | G8: -0.274 | H8: -0.352 | I8: -0.341 | J8: 0.862 | K8: 0.358
A9: AssetTurnover | B9: 0.902 | C9: 0.757 | D9: -0.202 | E9: -0.187 | F9: 1 | G9: 0.716 | H9: 0.021 | I9: -0.165 | J9: -0.136 | K9: 0.038
A10: EquityMultiplier | B10: 0.846 | C10: 0.343 | D10: -0.347 | E10: -0.274 | F10: 0.716 | G10: 1 | H10: 0.361 | I10: 0.098 | J10: -0.331 | K10: -0.522
A11: DebtToEquity | B11: 0.062 | C11: -0.268 | D11: -0.443 | E11: -0.352 | F11: 0.021 | G11: 0.361 | H11: 1 | I11: 0.945 | J11: -0.458 | K11: -0.432
A12: DebtRatio | B12: -0.175 | C12: -0.39 | D12: -0.42 | E12: -0.341 | F12: -0.165 | G12: 0.098 | H12: 0.945 | I12: 1 | J12: -0.433 | K12: -0.311
A13: InterestCoverage | B13: 0.034 | C13: 0.454 | D13: 0.868 | E13: 0.862 | F13: -0.136 | G13: -0.331 | H13: -0.458 | I13: -0.433 | J13: 1 | K13: 0.492
A14: CurrentRatio | B14: -0.133 | C14: 0.366 | D14: 0.451 | E14: 0.358 | F14: 0.038 | G14: -0.522 | H14: -0.432 | I14: -0.311 | J14: 0.492 | K14: 1
A16: Multicollinearity shortlist (|r| > 0.8) — kept out of one regression together:
A17: ROE × AssetTurnover r = +0.90
A18: ROE × EquityMultiplier r = +0.85
A19: NetMargin × EBITMargin r = +0.93
A20: NetMargin × InterestCoverage r = +0.87
A21: EBITMargin × InterestCoverage r = +0.86
A22: DebtToEquity × DebtRatio r = +0.95
A24: Regression uses D/E + NetMargin + log(assets) — none of these pairs.

Sheet Regression Analysis
A1: OLS — ROE ~ DebtToEquity + NetMargin + log(TotalAssets)
A2: pooled panel, 40 firm-years · computed in python (ols_regression.py) · significance flag is a live formula
A4: Variable | B4: Coefficient | C4: StdErr | D4: p-value | E4: CI low | F4: CI high | G4: p (cluster) | H4: Sig (p<0.05) | J4: Actual vs fitted (python residuals file)
A5: Intercept | B5: 0.9795 | C5: 0.3742 | D5: 0.0129 | E5: 0.2205 | F5: 1.7384 | G5: 0.0728 | H5: =IF(D5<0.05,"✓","·") | J5: Company | K5: Year | L5: ROE | M5: Fitted
A6: DebtToEquity | B6: 0.2754 | C6: 0.5954 | D6: 0.6465 | E6: -0.9322 | F6: 1.4829 | G6: 0.7291 | H6: =IF(D6<0.05,"✓","·") | J6: HUL | K6: FY2022 | L6: 0.1808 | M6: 0.2462
A7: NetMargin | B7: 0.4653 | C7: 0.7295 | D7: 0.5276 | E7: -1.0142 | F7: 1.9447 | G7: 0.5819 | H7: =IF(D7<0.05,"✓","·") | J7: HUL | K7: FY2023 | L7: 0.1984 | M7: 0.2425
A8: log_assets | B8: -0.0734 | C8: 0.0387 | D8: 0.0661 | E8: -0.152 | F8: 0.0052 | G8: 0.1695 | H8: =IF(D8<0.05,"✓","·") | J8: HUL | K8: FY2024 | L8: 0.1984 | M8: 0.2385
J9: HUL | K9: FY2025 | L9: 0.2165 | M9: 0.2437
A10: Model summary | J10: HUL | K10: FY2026 | L10: 0.3134 | M10: 0.2756
A11: R-squared | B11: 0.0954 | J11: ITC | K11: FY2022 | L11: 0.2452 | M11: 0.2809
A12: Adj R-squared | B12: 0.02 | J12: ITC | K12: FY2023 | L12: 0.2774 | M12: 0.2819
A13: F-statistic | B13: 1.265 | J13: ITC | K13: FY2024 | L13: 0.2827 | M13: 0.297
A14: F p-value | B14: 0.301 | J14: ITC | K14: FY2025 | L14: 0.5184 | M14: 0.3838
A15: Observations | B15: 40 | J15: ITC | K15: FY2026 | L15: 0.2901 | M15: 0.2824
A16: DoF residual | B16: 36 | J16: Dabur | K16: FY2022 | L16: 0.2444 | M16: 0.4221
J17: Dabur | K17: FY2023 | L17: 0.2184 | M17: 0.4086
A18: Plain-English read | J18: Dabur | K18: FY2024 | L18: 0.2182 | M18: 0.4071
A19: R² = 0.10: the three variables explain ~10% of ROE variation — LOW, and that is the finding, not a failure: | J19: Dabur | K19: FY2025 | L19: 0.189 | M19: 0.3822
A20: in this universe leverage barely varies (median D/E ≈ 0.04), so it cannot statistically separate high-ROE firms from low-ROE firms. | J20: Dabur | K20: FY2026 | L20: 0.1981 | M20: 0.3875
A21: The correlation sheet shows what does: AssetTurnover (r ≈ 0.90) and EquityMultiplier (r ≈ 0.85) — FMCG ROE is turnover- and float-driven. | J21: Marico | K21: FY2022 | L21: 0.3814 | M21: 0.452
A22: No coefficient survives firm-clustered errors at 5% — with 8 firms, pooled firm-years are not 40 independent observations. | J22: Marico | K22: FY2023 | L22: 0.3206 | M22: 0.4386
A23: D/E's coefficient is positive but insignificant — consistent with the threshold sheet: mild leverage coincides with higher ROE, more does not. | J23: Marico | K23: FY2024 | L23: 0.2997 | M23: 0.4438
J24: Marico | K24: FY2025 | L24: 0.3235 | M24: 0.4505
J25: Marico | K25: FY2026 | L25: 0.3342 | M25: 0.4277
J26: Colgate | K26: FY2022 | L26: 0.6217 | M26: 0.5055
J27: Colgate | K27: FY2023 | L27: 0.6101 | M27: 0.4988
J28: Colgate | K28: FY2024 | L28: 0.7065 | M28: 0.5059
J29: Colgate | K29: FY2025 | L29: 0.8636 | M29: 0.5119
J30: Colgate | K30: FY2026 | L30: 0.8365 | M30: 0.4925
J31: Nestle | K31: FY2022 | L31: 0.9723 | M31: 0.4073
J32: Nestle | K32: FY2023 | L32: 1.2196 | M32: 0.4144
J33: Nestle | K33: FY2024 | L33: 1.1775 | M33: 0.4029
J34: Nestle | K34: FY2025 | L34: 0.805 | M34: 0.4422
J35: Nestle | K35: FY2026 | L35: 0.6677 | M35: 0.3762
... J45: Emami | K45: FY2026 | L45: 0.2668 | M45: 0.5122

Sheet DCF - FCFF
A1: DCF - FCFF — 5-year projection, Gordon terminal value
A2: yellow = growth assumptions · flows/rates are formulas into Raw Data / WACC — nothing hardcoded
A4: Terminal growth g | B4: 0.04
A5: Forecast growth floor | B5: 0.03
A6: Forecast growth cap | B6: 0.15
A8: Historical FCFF per FY (formulas)
B9: FY2022 | C9: FY2023 | D9: FY2024 | E9: FY2025 | F9: FY2026
A10: HUL | B10: ='Raw Data'!S2+'Raw Data'!F2*(1-'Raw Data'!V2)-'Raw Data'!AB2 | C10: ='Raw Data'!S3+'Raw Data'!F3*(1-'Raw Data'!V3)-'Raw Data'!AB3 | D10: ='Raw Data'!S4+'Raw Data'!F4*(1-'Raw Data'!V4)-'Raw Data'!AB4 | E10: ='Raw Data'!S5+'Raw Data'!F5*(1-'Raw Data'!V5)-'Raw Data'!AB5 | F10: ='Raw Data'!S6+'Raw Data'!F6*(1-'Raw Data'!V6)-'Raw Data'!AB6
A11: ITC | B11: ='Raw Data'!S7+'Raw Data'!F7*(1-'Raw Data'!V7)-'Raw Data'!AB7 | C11: ='Raw Data'!S8+'Raw Data'!F8*(1-'Raw Data'!V8)-'Raw Data'!AB8 | D11: ='Raw Data'!S9+'Raw Data'!F9*(1-'Raw Data'!V9)-'Raw Data'!AB9 | E11: ='Raw Data'!S10+'Raw Data'!F10*(1-'Raw Data'!V10)-'Raw Data'!AB10 | F11: ='Raw Data'!S11+'Raw Data'!F11*(1-'Raw Data'!V11)-'Raw Data'!AB11
A12: Dabur | B12: ='Raw Data'!S12+'Raw Data'!F12*(1-'Raw Data'!V12)-'Raw Data'!AB12 | C12: ='Raw Data'!S13+'Raw Data'!F13*(1-'Raw Data'!V13)-'Raw Data'!AB13 | D12: ='Raw Data'!S14+'Raw Data'!F14*(1-'Raw Data'!V14)-'Raw Data'!AB14 | E12: ='Raw Data'!S15+'Raw Data'!F15*(1-'Raw Data'!V15)-'Raw Data'!AB15 | F12: ='Raw Data'!S16+'Raw Data'!F16*(1-'Raw Data'!V16)-'Raw Data'!AB16
A13: Marico | B13: ='Raw Data'!S17+'Raw Data'!F17*(1-'Raw Data'!V17)-'Raw Data'!AB17 | C13: ='Raw Data'!S18+'Raw Data'!F18*(1-'Raw Data'!V18)-'Raw Data'!AB18 | D13: ='Raw Data'!S19+'Raw Data'!F19*(1-'Raw Data'!V19)-'Raw Data'!AB19 | E13: ='Raw Data'!S20+'Raw Data'!F20*(1-'Raw Data'!V20)-'Raw Data'!AB20 | F13: ='Raw Data'!S21+'Raw Data'!F21*(1-'Raw Data'!V21)-'Raw Data'!AB21
A14: Colgate | B14: ='Raw Data'!S22+'Raw Data'!F22*(1-'Raw Data'!V22)-'Raw Data'!AB22 | C14: ='Raw Data'!S23+'Raw Data'!F23*(1-'Raw Data'!V23)-'Raw Data'!AB23 | D14: ='Raw Data'!S24+'Raw Data'!F24*(1-'Raw Data'!V24)-'Raw Data'!AB24 | E14: ='Raw Data'!S25+'Raw Data'!F25*(1-'Raw Data'!V25)-'Raw Data'!AB25 | F14: ='Raw Data'!S26+'Raw Data'!F26*(1-'Raw Data'!V26)-'Raw Data'!AB26
A15: Nestle | B15: ='Raw Data'!S27+'Raw Data'!F27*(1-'Raw Data'!V27)-'Raw Data'!AB27 | C15: ='Raw Data'!S28+'Raw Data'!F28*(1-'Raw Data'!V28)-'Raw Data'!AB28 | D15: ='Raw Data'!S29+'Raw Data'!F29*(1-'Raw Data'!V29)-'Raw Data'!AB29 | E15: ='Raw Data'!S30+'Raw Data'!F30*(1-'Raw Data'!V30)-'Raw Data'!AB30 | F15: ='Raw Data'!S31+'Raw Data'!F31*(1-'Raw Data'!V31)-'Raw Data'!AB31
A16: Godrej | B16: ='Raw Data'!S32+'Raw Data'!F32*(1-'Raw Data'!V32)-'Raw Data'!AB32 | C16: ='Raw Data'!S33+'Raw Data'!F33*(1-'Raw Data'!V33)-'Raw Data'!AB33 | D16: ='Raw Data'!S34+'Raw Data'!F34*(1-'Raw Data'!V34)-'Raw Data'!AB34 | E16: ='Raw Data'!S35+'Raw Data'!F35*(1-'Raw Data'!V35)-'Raw Data'!AB35 | F16: ='Raw Data'!S36+'Raw Data'!F36*(1-'Raw Data'!V36)-'Raw Data'!AB36
A17: Emami | B17: ='Raw Data'!S37+'Raw Data'!F37*(1-'Raw Data'!V37)-'Raw Data'!AB37 | C17: ='Raw Data'!S38+'Raw Data'!F38*(1-'Raw Data'!V38)-'Raw Data'!AB38 | D17: ='Raw Data'!S39+'Raw Data'!F39*(1-'Raw Data'!V39)-'Raw Data'!AB39 | E17: ='Raw Data'!S40+'Raw Data'!F40*(1-'Raw Data'!V40)-'Raw Data'!AB40 | F17: ='Raw Data'!S41+'Raw Data'!F41*(1-'Raw Data'!V41)-'Raw Data'!AB41
A20: Company | B20: Base FCFF | C20: Rev CAGR raw | D20: g used | E20: Rate | F20: Y1 | G20: Y2 | H20: Y3 | I20: Y4 | J20: Y5 | K20: PV(Y1..Y5) | L20: TV | M20: PV(TV) | N20: PV total | O20: Net debt | P20: Equity value | Q20: Shares (Cr) | R20: Value/share | S20: Mkt price | T20: Upside
A21: HUL | B21: =AVERAGE(D10:F10) | C21: =('Raw Data'!C6/'Raw Data'!C2)^(1/4)-1 | D21: =MIN(MAX(C21,$B$5),$B$6) | E21: ='WACC'!M10 | F21: =B21*(1+D21)^1 | G21: =B21*(1+D21)^2 | H21: =B21*(1+D21)^3 | I21: =B21*(1+D21)^4 | J21: =B21*(1+D21)^5 | K21: =SUMPRODUCT(F21:J21/POWER(1+E21,{1,2,3,4,5})) | L21: =IF(E21-$B$4<0.01,NA(),J21*(1+$B$4)/(E21-$B$4)) | M21: =L21/POWER(1+E21,5) | N21: =K21+M21 | O21: ='Raw Data'!M6-'Raw Data'!O6 | P21: =N21-O21 | Q21: ='Raw Data'!AD6 | R21: =P21/Q21 | S21: ='Market Data'!C2 | T21: =R21/S21-1
A22: ITC | B22: =AVERAGE(D11:F11) | C22: =('Raw Data'!C11/'Raw Data'!C7)^(1/4)-1 | D22: =MIN(MAX(C22,$B$5),$B$6) | E22: ='WACC'!M11 | F22: =B22*(1+D22)^1 | G22: =B22*(1+D22)^2 | H22: =B22*(1+D22)^3 | I22: =B22*(1+D22)^4 | J22: =B22*(1+D22)^5 | K22: =SUMPRODUCT(F22:J22/POWER(1+E22,{1,2,3,4,5})) | L22: =IF(E22-$B$4<0.01,NA(),J22*(1+$B$4)/(E22-$B$4)) | M22: =L22/POWER(1+E22,5) | N22: =K22+M22 | O22: ='Raw Data'!M11-'Raw Data'!O11 | P22: =N22-O22 | Q22: ='Raw Data'!AD11 | R22: =P22/Q22 | S22: ='Market Data'!C3 | T22: =R22/S22-1
A23: Dabur | B23: =AVERAGE(D12:F12) | C23: =('Raw Data'!C16/'Raw Data'!C12)^(1/4)-1 | D23: =MIN(MAX(C23,$B$5),$B$6) | E23: ='WACC'!M12 | F23: =B23*(1+D23)^1 | G23: =B23*(1+D23)^2 | H23: =B23*(1+D23)^3 | I23: =B23*(1+D23)^4 | J23: =B23*(1+D23)^5 | K23: =SUMPRODUCT(F23:J23/POWER(1+E23,{1,2,3,4,5})) | L23: =IF(E23-$B$4<0.01,NA(),J23*(1+$B$4)/(E23-$B$4)) | M23: =L23/POWER(1+E23,5) | N23: =K23+M23 | O23: ='Raw Data'!M16-'Raw Data'!O16 | P23: =N23-O23 | Q23: ='Raw Data'!AD16 | R23: =P23/Q23 | S23: ='Market Data'!C4 | T23: =R23/S23-1
A24: Marico | B24: =AVERAGE(D13:F13) | C24: =('Raw Data'!C21/'Raw Data'!C17)^(1/4)-1 | D24: =MIN(MAX(C24,$B$5),$B$6) | E24: ='WACC'!M13 | F24: =B24*(1+D24)^1 | G24: =B24*(1+D24)^2 | H24: =B24*(1+D24)^3 | I24: =B24*(1+D24)^4 | J24: =B24*(1+D24)^5 | K24: =SUMPRODUCT(F24:J24/POWER(1+E24,{1,2,3,4,5})) | L24: =IF(E24-$B$4<0.01,NA(),J24*(1+$B$4)/(E24-$B$4)) | M24: =L24/POWER(1+E24,5) | N24: =K24+M24 | O24: ='Raw Data'!M21-'Raw Data'!O21 | P24: =N24-O24 | Q24: ='Raw Data'!AD21 | R24: =P24/Q24 | S24: ='Market Data'!C5 | T24: =R24/S24-1
A25: Colgate | B25: =AVERAGE(D14:F14) | C25: =('Raw Data'!C26/'Raw Data'!C22)^(1/4)-1 | D25: =MIN(MAX(C25,$B$5),$B$6) | E25: ='WACC'!M14 | F25: =B25*(1+D25)^1 | G25: =B25*(1+D25)^2 | H25: =B25*(1+D25)^3 | I25: =B25*(1+D25)^4 | J25: =B25*(1+D25)^5 | K25: =SUMPRODUCT(F25:J25/POWER(1+E25,{1,2,3,4,5})) | L25: =IF(E25-$B$4<0.01,NA(),J25*(1+$B$4)/(E25-$B$4)) | M25: =L25/POWER(1+E25,5) | N25: =K25+M25 | O25: ='Raw Data'!M26-'Raw Data'!O26 | P25: =N25-O25 | Q25: ='Raw Data'!AD26 | R25: =P25/Q25 | S25: ='Market Data'!C6 | T25: =R25/S25-1
